<?xml version="1.0" ?>
<!-- =================================================================================== -->
<!-- |    This document was autogenerated by xacro from sia20d.xacro                   | -->
<!-- |    EDITING THIS FILE BY HAND IS NOT RECOMMENDED                                 | -->
<!-- =================================================================================== -->
<robot name="motoman_sia20d" xmlns:xacro="http://ros.org/wiki/xacro">
  <!-- link list -->
  <link name="motoman_base_link">
    <visual>
      <geometry>
        <mesh filename="package://motoman_sia20d_support/meshes/sia20d/visual/MOTOMAN_BASE.stl"/>
      </geometry>
      <material name="blue">
        <color rgba="0 0 1 1"/>
      </material>
    </visual>
    <collision>
      <geometry>
        <mesh filename="package://motoman_sia20d_support/meshes/sia20d/collision/MOTOMAN_BASE.stl"/>
      </geometry>
      <material name="yellow">
        <color rgba="0 1 1 1"/>
      </material>
    </collision>
    <inertial>
      <origin rpy="0 0 0" xyz="0 0 0"/>
      <mass value="1"/>
      <inertia ixx="0.0226667" ixy="0.0" ixz="0.0" iyy="0.0226667" iyz="0.0" izz="0.0226667"/>
    </inertial>
  </link>
  <link name="motoman_link_s">
    <visual>
      <origin rpy="0 0 3.1416" xyz="0 0 0"/>
      <geometry>
        <mesh filename="package://motoman_sia20d_support/meshes/sia20d/visual/MOTOMAN_AXIS_S.stl"/>
      </geometry>
      <material name="silver">
        <color rgba="0.8 0.8 0.8 1"/>
      </material>
    </visual>
    <collision>
      <origin rpy="0 0 3.1416" xyz="0 0 0"/>
      <geometry>
        <mesh filename="package://motoman_sia20d_support/meshes/sia20d/collision/MOTOMAN_AXIS_S.stl"/>
      </geometry>
      <material name="yellow"/>
    </collision>
    <inertial>
      <origin rpy="0 0 0" xyz="0 0 0"/>
      <mass value="1"/>
      <inertia ixx="0.0226667" ixy="0.0" ixz="0.0" iyy="0.0226667" iyz="0.0" izz="0.0226667"/>
    </inertial>
  </link>
  <link name="motoman_link_l">
    <visual>
      <origin rpy="1.57 3.1416 3.1416" xyz="0 0 0"/>
      <geometry>
        <mesh filename="package://motoman_sia20d_support/meshes/sia20d/visual/MOTOMAN_AXIS_L.stl"/>
      </geometry>
      <material name="blue"/>
    </visual>
    <collision>
      <origin rpy="1.57 3.1416 3.1416" xyz="0 0 0"/>
      <geometry>
        <mesh filename="package://motoman_sia20d_support/meshes/sia20d/collision/MOTOMAN_AXIS_L.stl"/>
      </geometry>
      <material name="yellow"/>
    </collision>
    <inertial>
      <origin rpy="0 0 0" xyz="0 0 0"/>
      <mass value="1"/>
      <inertia ixx="0.0226667" ixy="0.0" ixz="0.0" iyy="0.0226667" iyz="0.0" izz="0.0226667"/>
    </inertial>
  </link>
  <link name="motoman_link_e">
    <visual>
      <origin rpy="0 0 0" xyz="0 0 0"/>
      <geometry>
        <mesh filename="package://motoman_sia20d_support/meshes/sia20d/visual/MOTOMAN_AXIS_E.stl"/>
      </geometry>
      <material name="silver"/>
    </visual>
    <collision>
      <origin rpy="0 0 0" xyz="0 0 0"/>
      <geometry>
        <mesh filename="package://motoman_sia20d_support/meshes/sia20d/collision/MOTOMAN_AXIS_E.stl"/>
      </geometry>
      <material name="yellow"/>
    </collision>
    <inertial>
      <origin rpy="0 0 0" xyz="0 0 0"/>
      <mass value="1"/>
      <inertia ixx="0.0226667" ixy="0.0" ixz="0.0" iyy="0.0226667" iyz="0.0" izz="0.0226667"/>
    </inertial>
  </link>
  <link name="motoman_link_u">
    <visual>
      <origin rpy="1.57 -3.1415 3.1416" xyz="0 0 0"/>
      <geometry>
        <mesh filename="package://motoman_sia20d_support/meshes/sia20d/visual/MOTOMAN_AXIS_U.stl"/>
      </geometry>
      <material name="blue"/>
    </visual>
    <collision>
      <origin rpy="1.57 -3.1415 3.1416" xyz="0 0 0"/>
      <geometry>
        <mesh filename="package://motoman_sia20d_support/meshes/sia20d/collision/MOTOMAN_AXIS_U.stl"/>
      </geometry>
      <material name="yellow"/>
    </collision>
    <inertial>
      <origin rpy="0 0 0" xyz="0 0 0"/>
      <mass value="1"/>
      <inertia ixx="0.0226667" ixy="0.0" ixz="0.0" iyy="0.0226667" iyz="0.0" izz="0.0226667"/>
    </inertial>
  </link>
  <link name="motoman_link_r">
    <visual>
      <origin rpy="0 0 0" xyz="0 0 0"/>
      <geometry>
        <mesh filename="package://motoman_sia20d_support/meshes/sia20d/visual/MOTOMAN_AXIS_R.stl"/>
      </geometry>
      <material name="silver"/>
    </visual>
    <collision>
      <origin rpy="0 0 0" xyz="0 0 0"/>
      <geometry>
        <mesh filename="package://motoman_sia20d_support/meshes/sia20d/collision/MOTOMAN_AXIS_R.stl"/>
      </geometry>
      <material name="yellow"/>
    </collision>
    <inertial>
      <origin rpy="0 0 0" xyz="0 0 0"/>
      <mass value="1"/>
      <inertia ixx="0.0226667" ixy="0.0" ixz="0.0" iyy="0.0226667" iyz="0.0" izz="0.0226667"/>
    </inertial>
  </link>
  <link name="motoman_link_b">
    <visual>
      <origin rpy="-1.57 0 0" xyz="0 0 0"/>
      <geometry>
        <mesh filename="package://motoman_sia20d_support/meshes/sia20d/visual/MOTOMAN_AXIS_B.stl"/>
      </geometry>
      <material name="blue"/>
    </visual>
    <collision>
      <origin rpy="-1.57 0 0" xyz="0 0 0"/>
      <geometry>
        <mesh filename="package://motoman_sia20d_support/meshes/sia20d/collision/MOTOMAN_AXIS_B.stl"/>
      </geometry>
      <material name="yellow"/>
    </collision>
    <inertial>
      <origin rpy="0 0 0" xyz="0 0 0"/>
      <mass value="1"/>
      <inertia ixx="0.0226667" ixy="0.0" ixz="0.0" iyy="0.0226667" iyz="0.0" izz="0.0226667"/>
    </inertial>
  </link>
  <link name="motoman_link_t">
    <visual>
      <geometry>
        <mesh filename="package://motoman_sia20d_support/meshes/sia20d/visual/MOTOMAN_AXIS_T.stl"/>
      </geometry>
      <material name="silver"/>
    </visual>
    <collision>
      <geometry>
        <mesh filename="package://motoman_sia20d_support/meshes/sia20d/collision/MOTOMAN_AXIS_T.stl"/>
      </geometry>
      <material name="yellow"/>
    </collision>
    <inertial>
      <origin rpy="0 0 0" xyz="0 0 0"/>
      <mass value="1"/>
      <inertia ixx="0.0226667" ixy="0.0" ixz="0.0" iyy="0.0226667" iyz="0.0" izz="0.0226667"/>
    </inertial>
  </link>
  <!--  <link name="${prefix}tool0" /> -->
  <!-- end of link list -->
  <!-- joint list -->
  <joint name="motoman_joint_s" type="revolute">
    <parent link="motoman_base_link"/>
    <child link="motoman_link_s"/>
    <origin rpy="0 0 0" xyz="0 0 0.41"/>
    <axis xyz="0 0 1"/>
    <limit effort="100" lower="-3.1416" upper="3.1416" velocity="2.26"/>
  </joint>
  <joint name="motoman_joint_l" type="revolute">
    <parent link="motoman_link_s"/>
    <child link="motoman_link_l"/>
    <origin rpy="0 0 0" xyz="0 0 0"/>
    <axis xyz="0 1 0"/>
    <limit effort="100" lower="-1.91" upper="1.91" velocity="2.26"/>
  </joint>
  <joint name="motoman_joint_e" type="revolute">
    <parent link="motoman_link_l"/>
    <child link="motoman_link_e"/>
    <origin rpy="0 0 0" xyz="0 0 0.49"/>
    <axis xyz="0 0 1"/>
    <limit effort="100" lower="-2.96" upper="2.96" velocity="2.96"/>
  </joint>
  <joint name="motoman_joint_u" type="revolute">
    <parent link="motoman_link_e"/>
    <child link="motoman_link_u"/>
    <origin rpy="0 0 0" xyz="0 0 0"/>
    <axis xyz="0 -1 0"/>
    <limit effort="100" lower="-2.26" upper="2.26" velocity="2.96"/>
  </joint>
  <joint name="motoman_joint_r" type="revolute">
    <parent link="motoman_link_u"/>
    <child link="motoman_link_r"/>
    <origin rpy="0 0 0" xyz="0 0 0.420"/>
    <axis xyz="0 0 -1"/>
    <limit effort="100" lower="-3.1416" upper="3.1416" velocity="3.48"/>
  </joint>
  <joint name="motoman_joint_b" type="revolute">
    <parent link="motoman_link_r"/>
    <child link="motoman_link_b"/>
    <origin rpy="0 0 0" xyz="0 0 0"/>
    <axis xyz="0 -1 0"/>
    <limit effort="100" lower="-1.91" upper="1.91" velocity="3.48"/>
  </joint>
  <joint name="motoman_joint_t" type="revolute">
    <parent link="motoman_link_b"/>
    <child link="motoman_link_t"/>
    <origin rpy="0 0 0" xyz="0 0 0.18"/>
    <axis xyz="0 0 -1"/>
    <limit effort="100" lower="-3.1416" upper="3.1416" velocity="6.97"/>
  </joint>
  <!-- end of joint list -->
  <gazebo reference="motoman_base_link">
    <material>Gazebo/White</material>
    <turnGravityOff>true</turnGravityOff>
  </gazebo>
  <gazebo reference="motoman_link_s">
    <material>Gazebo/Blue</material>
    <turnGravityOff>true</turnGravityOff>
  </gazebo>
  <gazebo reference="motoman_link_l">
    <material>Gazebo/Silver</material>
    <turnGravityOff>true</turnGravityOff>
  </gazebo>
  <gazebo reference="motoman_link_e">
    <material>Gazebo/Blue</material>
    <turnGravityOff>true</turnGravityOff>
  </gazebo>
  <gazebo reference="motoman_link_u">
    <material>Gazebo/Silver</material>
    <turnGravityOff>true</turnGravityOff>
  </gazebo>
  <gazebo reference="motoman_link_r">
    <material>Gazebo/Blue</material>
    <turnGravityOff>true</turnGravityOff>
  </gazebo>
  <gazebo reference="motoman_link_b">
    <material>Gazebo/Silver</material>
    <turnGravityOff>true</turnGravityOff>
  </gazebo>
  <gazebo reference="motoman_link_t">
    <material>Gazebo/Blue</material>
    <turnGravityOff>true</turnGravityOff>
  </gazebo>
  <transmission name="trans_motoman_joint_s">
    <type>transmission_interface/SimpleTransmission</type>
    <joint name="motoman_joint_s">
      <hardwareInterface>hardware_interface/EffortJointInterface</hardwareInterface>
    </joint>
    <actuator name="motoman_joint_s_motor">
      <hardwareInterface>hardware_interface/EffortJointInterface</hardwareInterface>
      <mechanicalReduction>1</mechanicalReduction>
    </actuator>
  </transmission>
  <transmission name="trans_motoman_joint_l">
    <type>transmission_interface/SimpleTransmission</type>
    <joint name="motoman_joint_l">
      <hardwareInterface>hardware_interface/EffortJointInterface</hardwareInterface>
    </joint>
    <actuator name="motoman_joint_l_motor">
      <hardwareInterface>hardware_interface/EffortJointInterface</hardwareInterface>
      <mechanicalReduction>1</mechanicalReduction>
    </actuator>
  </transmission>
  <transmission name="trans_motoman_joint_e">
    <type>transmission_interface/SimpleTransmission</type>
    <joint name="motoman_joint_e">
      <hardwareInterface>hardware_interface/EffortJointInterface</hardwareInterface>
    </joint>
    <actuator name="motoman_joint_e_motor">
      <hardwareInterface>hardware_interface/EffortJointInterface</hardwareInterface>
      <mechanicalReduction>1</mechanicalReduction>
    </actuator>
  </transmission>
  <transmission name="trans_motoman_joint_u">
    <type>transmission_interface/SimpleTransmission</type>
    <joint name="motoman_joint_u">
      <hardwareInterface>hardware_interface/EffortJointInterface</hardwareInterface>
    </joint>
    <actuator name="motoman_joint_u_motor">
      <hardwareInterface>hardware_interface/EffortJointInterface</hardwareInterface>
      <mechanicalReduction>1</mechanicalReduction>
    </actuator>
  </transmission>
  <transmission name="trans_motoman_joint_r">
    <type>transmission_interface/SimpleTransmission</type>
    <joint name="motoman_joint_r">
      <hardwareInterface>hardware_interface/EffortJointInterface</hardwareInterface>
    </joint>
    <actuator name="motoman_joint_r_motor">
      <hardwareInterface>hardware_interface/EffortJointInterface</hardwareInterface>
      <mechanicalReduction>1</mechanicalReduction>
    </actuator>
  </transmission>
  <transmission name="trans_motoman_joint_b">
    <type>transmission_interface/SimpleTransmission</type>
    <joint name="motoman_joint_b">
      <hardwareInterface>hardware_interface/EffortJointInterface</hardwareInterface>
    </joint>
    <actuator name="motoman_joint_b_motor">
      <hardwareInterface>hardware_interface/EffortJointInterface</hardwareInterface>
      <mechanicalReduction>1</mechanicalReduction>
    </actuator>
  </transmission>
  <transmission name="trans_motoman_joint_t">
    <type>transmission_interface/SimpleTransmission</type>
    <joint name="motoman_joint_t">
      <hardwareInterface>hardware_interface/EffortJointInterface</hardwareInterface>
    </joint>
    <actuator name="motoman_joint_t_motor">
      <hardwareInterface>hardware_interface/EffortJointInterface</hardwareInterface>
      <mechanicalReduction>1</mechanicalReduction>
    </actuator>
  </transmission>
  <!-- gripper -->
  <link name="motoman_finger_1">
    <inertial>
      <mass value=".1"/>
      <origin rpy="0 0 0" xyz="0 0 0"/>
      <inertia ixx="0.1" ixy="0" ixz="0" iyy="0.1" iyz="0" izz="0.1"/>
    </inertial>
    <collision name="motoman_right_finger_collision">
      <origin rpy="0 0 0" xyz="0 0 0"/>
      <geometry>
        <mesh filename="package://motoman_sia20d_support/meshes/sia20d/visual/motoman_finger_1.STL" scale="1 1 1"/>
      </geometry>
    </collision>
    <visual name="motoman_right_finger_visual">
      <origin rpy="0 0 0" xyz="0 0 0"/>
      <geometry>
        <mesh filename="package://motoman_sia20d_support/meshes/sia20d/collision/motoman_finger_1.STL" scale="1 1 1"/>
      </geometry>
    </visual>
  </link>
  <link name="motoman_finger_2">
    <inertial>
      <mass value=".1"/>
      <origin rpy="0 0 0" xyz="0 0 0"/>
      <inertia ixx="0.001" ixy="0" ixz="0" iyy="0.001" iyz="0" izz="0.001"/>
    </inertial>
    <collision name="motoman_left_finger_collision">
      <origin rpy="0 0 0" xyz="0 0 0"/>
      <geometry>
        <mesh filename="package://motoman_sia20d_support/meshes/sia20d/collision/motoman_finger_2.STL" scale="1 1 1"/>
      </geometry>
    </collision>
    <visual name="motoman_left_finger_visual">
      <origin rpy="0 0 0" xyz="0 0 0"/>
      <geometry>
        <mesh filename="package://motoman_sia20d_support/meshes/sia20d/visual/motoman_finger_2.STL" scale="1 1 1"/>
      </geometry>
    </visual>
  </link>
  <joint name="motoman_prism1" type="prismatic">
    <parent link="motoman_link_t"/>
    <child link="motoman_finger_1"/>
    <origin rpy="1.5708 0     0" xyz="0     0     0.00821"/>
    <axis xyz="-1  0  0"/>
    <limit effort="100.0" lower="-0.02" upper="0.0" velocity="10.0"/>
  </joint>
  <joint name="motoman_prism2" type="prismatic">
    <parent link="motoman_link_t"/>
    <child link="motoman_finger_2"/>
    <origin rpy="1.5708   0      -3.14159" xyz="0     0     0.00821"/>
    <axis xyz="-1  0  0"/>
    <limit effort="1000.0" lower="-0.02" upper="0.0" velocity="10.0"/>
  </joint>
  <gazebo reference="motoman_finger_1">
    <material>Gazebo/White</material>
    <turnGravityOff>true</turnGravityOff>
  </gazebo>
  <gazebo reference="motoman_finger_2">
    <material>Gazebo/White</material>
    <turnGravityOff>true</turnGravityOff>
  </gazebo>
  <transmission name="trans_motoman_prism1">
    <type>transmission_interface/SimpleTransmission</type>
    <joint name="motoman_prism1">
      <hardwareInterface>hardware_interface/EffortJointInterface</hardwareInterface>
    </joint>
    <actuator name="motoman_prism1_motor">
      <hardwareInterface>hardware_interface/EffortJointInterface</hardwareInterface>
      <mechanicalReduction>1</mechanicalReduction>
    </actuator>
  </transmission>
  <transmission name="trans_motoman_prism2">
    <type>transmission_interface/SimpleTransmission</type>
    <joint name="motoman_prism2">
      <hardwareInterface>hardware_interface/EffortJointInterface</hardwareInterface>
    </joint>
    <actuator name="motoman_prism2_motor">
      <hardwareInterface>hardware_interface/EffortJointInterface</hardwareInterface>
      <mechanicalReduction>1</mechanicalReduction>
    </actuator>
  </transmission>
</robot>

