<?xml version="1.0" encoding="UTF-8"?>
<robot xmlns:xacro="http://ros.org/wiki/xacro">
   <xacro:macro name="motoman_sia20d" params="prefix">
      <!-- link list -->
      <link name="${prefix}base_link">
         <visual>
            <geometry>
               <mesh filename="package://motoman_sia20d_support/meshes/sia20d/visual/MOTOMAN_BASE.stl" />
            </geometry>
            <material name="blue">
               <color rgba="0 0 1 1" />
            </material>
         </visual>
         <collision>
            <geometry>
               <mesh filename="package://motoman_sia20d_support/meshes/sia20d/collision/MOTOMAN_BASE.stl" />
            </geometry>
            <material name="yellow">
               <color rgba="0 1 1 1" />
            </material>
         </collision>
         <inertial>
            <origin xyz="0 0 0" rpy="0 0 0" />
            <mass value="1" />
            <inertia ixx="0.0226667" ixy="0.0" ixz="0.0" iyy="0.0226667" iyz="0.0" izz="0.0226667" />
         </inertial>
      </link>
      <link name="${prefix}link_s">
         <visual>
            <origin rpy="0 0 3.1416" xyz="0 0 0" />
            <geometry>
               <mesh filename="package://motoman_sia20d_support/meshes/sia20d/visual/MOTOMAN_AXIS_S.stl" />
            </geometry>
            <material name="silver">
               <color rgba="0.8 0.8 0.8 1" />
            </material>
         </visual>
         <collision>
            <origin rpy="0 0 3.1416" xyz="0 0 0" />
            <geometry>
               <mesh filename="package://motoman_sia20d_support/meshes/sia20d/collision/MOTOMAN_AXIS_S.stl" />
            </geometry>
            <material name="yellow" />
         </collision>
         <inertial>
            <origin xyz="0 0 0" rpy="0 0 0" />
            <mass value="1" />
            <inertia ixx="0.0226667" ixy="0.0" ixz="0.0" iyy="0.0226667" iyz="0.0" izz="0.0226667" />
         </inertial>
      </link>
      <link name="${prefix}link_l">
         <visual>
            <origin rpy="1.57 3.1416 3.1416" xyz="0 0 0" />
            <geometry>
               <mesh filename="package://motoman_sia20d_support/meshes/sia20d/visual/MOTOMAN_AXIS_L.stl" />
            </geometry>
            <material name="blue" />
         </visual>
         <collision>
            <origin rpy="1.57 3.1416 3.1416" xyz="0 0 0" />
            <geometry>
               <mesh filename="package://motoman_sia20d_support/meshes/sia20d/collision/MOTOMAN_AXIS_L.stl" />
            </geometry>
            <material name="yellow" />
         </collision>
         <inertial>
            <origin xyz="0 0 0" rpy="0 0 0" />
            <mass value="1" />
            <inertia ixx="0.0226667" ixy="0.0" ixz="0.0" iyy="0.0226667" iyz="0.0" izz="0.0226667" />
         </inertial>
      </link>
      <link name="${prefix}link_e">
         <visual>
            <origin rpy="0 0 0" xyz="0 0 0" />
            <geometry>
               <mesh filename="package://motoman_sia20d_support/meshes/sia20d/visual/MOTOMAN_AXIS_E.stl" />
            </geometry>
            <material name="silver" />
         </visual>
         <collision>
            <origin rpy="0 0 0" xyz="0 0 0" />
            <geometry>
               <mesh filename="package://motoman_sia20d_support/meshes/sia20d/collision/MOTOMAN_AXIS_E.stl" />
            </geometry>
            <material name="yellow" />
         </collision>
         <inertial>
            <origin xyz="0 0 0" rpy="0 0 0" />
            <mass value="1" />
            <inertia ixx="0.0226667" ixy="0.0" ixz="0.0" iyy="0.0226667" iyz="0.0" izz="0.0226667" />
         </inertial>
      </link>
      <link name="${prefix}link_u">
         <visual>
            <origin rpy="1.57 -3.1415 3.1416" xyz="0 0 0" />
            <geometry>
               <mesh filename="package://motoman_sia20d_support/meshes/sia20d/visual/MOTOMAN_AXIS_U.stl" />
            </geometry>
            <material name="blue" />
         </visual>
         <collision>
            <origin rpy="1.57 -3.1415 3.1416" xyz="0 0 0" />
            <geometry>
               <mesh filename="package://motoman_sia20d_support/meshes/sia20d/collision/MOTOMAN_AXIS_U.stl" />
            </geometry>
            <material name="yellow" />
         </collision>
         <inertial>
            <origin xyz="0 0 0" rpy="0 0 0" />
            <mass value="1" />
            <inertia ixx="0.0226667" ixy="0.0" ixz="0.0" iyy="0.0226667" iyz="0.0" izz="0.0226667" />
         </inertial>
      </link>
      <link name="${prefix}link_r">
         <visual>
            <origin rpy="0 0 0" xyz="0 0 0" />
            <geometry>
               <mesh filename="package://motoman_sia20d_support/meshes/sia20d/visual/MOTOMAN_AXIS_R.stl" />
            </geometry>
            <material name="silver" />
         </visual>
         <collision>
            <origin rpy="0 0 0" xyz="0 0 0" />
            <geometry>
               <mesh filename="package://motoman_sia20d_support/meshes/sia20d/collision/MOTOMAN_AXIS_R.stl" />
            </geometry>
            <material name="yellow" />
         </collision>
         <inertial>
            <origin xyz="0 0 0" rpy="0 0 0" />
            <mass value="1" />
            <inertia ixx="0.0226667" ixy="0.0" ixz="0.0" iyy="0.0226667" iyz="0.0" izz="0.0226667" />
         </inertial>
      </link>
      <link name="${prefix}link_b">
         <visual>
            <origin rpy="-1.57 0 0" xyz="0 0 0" />
            <geometry>
               <mesh filename="package://motoman_sia20d_support/meshes/sia20d/visual/MOTOMAN_AXIS_B.stl" />
            </geometry>
            <material name="blue" />
         </visual>
         <collision>
            <origin rpy="-1.57 0 0" xyz="0 0 0" />
            <geometry>
               <mesh filename="package://motoman_sia20d_support/meshes/sia20d/collision/MOTOMAN_AXIS_B.stl" />
            </geometry>
            <material name="yellow" />
         </collision>
         <inertial>
            <origin xyz="0 0 0" rpy="0 0 0" />
            <mass value="1" />
            <inertia ixx="0.0226667" ixy="0.0" ixz="0.0" iyy="0.0226667" iyz="0.0" izz="0.0226667" />
         </inertial>
      </link>
      <link name="${prefix}link_t">
         <visual>
            <geometry>
               <mesh filename="package://motoman_sia20d_support/meshes/sia20d/visual/MOTOMAN_AXIS_T.stl" />
            </geometry>
            <material name="silver" />
         </visual>
         <collision>
            <geometry>
               <mesh filename="package://motoman_sia20d_support/meshes/sia20d/collision/MOTOMAN_AXIS_T.stl" />
            </geometry>
            <material name="yellow" />
         </collision>
         <inertial>
            <origin xyz="0 0 0" rpy="0 0 0" />
            <mass value="1" />
            <inertia ixx="0.0226667" ixy="0.0" ixz="0.0" iyy="0.0226667" iyz="0.0" izz="0.0226667" />
         </inertial>
      </link>
      <!--  <link name="${prefix}tool0" /> -->
      <!-- end of link list -->
      <!-- joint list -->
      <joint name="${prefix}joint_s" type="revolute">
         <parent link="${prefix}base_link" />
         <child link="${prefix}link_s" />
         <origin xyz="0 0 0.41" rpy="0 0 0" />
         <axis xyz="0 0 1" />
         <limit lower="-3.1416" upper="3.1416" effort="100" velocity="2.26" />
      </joint>
      <joint name="${prefix}joint_l" type="revolute">
         <parent link="${prefix}link_s" />
         <child link="${prefix}link_l" />
         <origin xyz="0 0 0" rpy="0 0 0" />
         <axis xyz="0 1 0" />
         <limit lower="-1.91" upper="1.91" effort="100" velocity="2.26" />
      </joint>
      <joint name="${prefix}joint_e" type="revolute">
         <parent link="${prefix}link_l" />
         <child link="${prefix}link_e" />
         <origin xyz="0 0 0.49" rpy="0 0 0" />
         <axis xyz="0 0 1" />
         <limit lower="-2.96" upper="2.96" effort="100" velocity="2.96" />
      </joint>
      <joint name="${prefix}joint_u" type="revolute">
         <parent link="${prefix}link_e" />
         <child link="${prefix}link_u" />
         <origin xyz="0 0 0" rpy="0 0 0" />
         <axis xyz="0 -1 0" />
         <limit lower="-2.26" upper="2.26" effort="100" velocity="2.96" />
      </joint>
      <joint name="${prefix}joint_r" type="revolute">
         <parent link="${prefix}link_u" />
         <child link="${prefix}link_r" />
         <origin xyz="0 0 0.420" rpy="0 0 0" />
         <axis xyz="0 0 -1" />
         <limit lower="-3.1416" upper="3.1416" effort="100" velocity="3.48" />
      </joint>
      <joint name="${prefix}joint_b" type="revolute">
         <parent link="${prefix}link_r" />
         <child link="${prefix}link_b" />
         <origin xyz="0 0 0" rpy="0 0 0" />
         <axis xyz="0 -1 0" />
         <limit lower="-1.91" upper="1.91" effort="100" velocity="3.48" />
      </joint>
      <joint name="${prefix}joint_t" type="revolute">
         <parent link="${prefix}link_b" />
         <child link="${prefix}link_t" />
         <origin xyz="0 0 0.18" rpy="0 0 0" />
         <axis xyz="0 0 -1" />
         <limit lower="-3.1416" upper="3.1416" effort="100" velocity="6.97" />
      </joint>
      <!-- end of joint list -->
      <gazebo reference="${prefix}base_link">
         <material>Gazebo/White</material>
         <turnGravityOff>true</turnGravityOff>
      </gazebo>
      <gazebo reference="${prefix}link_s">
         <material>Gazebo/Blue</material>
         <turnGravityOff>true</turnGravityOff>
      </gazebo>
      <gazebo reference="${prefix}link_l">
         <material>Gazebo/Silver</material>
         <turnGravityOff>true</turnGravityOff>
      </gazebo>
      <gazebo reference="${prefix}link_e">
         <material>Gazebo/Blue</material>
         <turnGravityOff>true</turnGravityOff>
      </gazebo>
      <gazebo reference="${prefix}link_u">
         <material>Gazebo/Silver</material>
         <turnGravityOff>true</turnGravityOff>
      </gazebo>
      <gazebo reference="${prefix}link_r">
         <material>Gazebo/Blue</material>
         <turnGravityOff>true</turnGravityOff>
      </gazebo>
      <gazebo reference="${prefix}link_b">
         <material>Gazebo/Silver</material>
         <turnGravityOff>true</turnGravityOff>
      </gazebo>
      <gazebo reference="${prefix}link_t">
         <material>Gazebo/Blue</material>
         <turnGravityOff>true</turnGravityOff>
      </gazebo>
      <transmission name="trans_${prefix}joint_s">
         <type>transmission_interface/SimpleTransmission</type>
         <joint name="${prefix}joint_s">
            <hardwareInterface>hardware_interface/EffortJointInterface</hardwareInterface>
         </joint>
         <actuator name="${prefix}joint_s_motor">
            <hardwareInterface>hardware_interface/EffortJointInterface</hardwareInterface>
            <mechanicalReduction>1</mechanicalReduction>
         </actuator>
      </transmission>
      <transmission name="trans_${prefix}joint_l">
         <type>transmission_interface/SimpleTransmission</type>
         <joint name="${prefix}joint_l">
            <hardwareInterface>hardware_interface/EffortJointInterface</hardwareInterface>
         </joint>
         <actuator name="${prefix}joint_l_motor">
            <hardwareInterface>hardware_interface/EffortJointInterface</hardwareInterface>
            <mechanicalReduction>1</mechanicalReduction>
         </actuator>
      </transmission>
      <transmission name="trans_${prefix}joint_e">
         <type>transmission_interface/SimpleTransmission</type>
         <joint name="${prefix}joint_e">
            <hardwareInterface>hardware_interface/EffortJointInterface</hardwareInterface>
         </joint>
         <actuator name="${prefix}joint_e_motor">
            <hardwareInterface>hardware_interface/EffortJointInterface</hardwareInterface>
            <mechanicalReduction>1</mechanicalReduction>
         </actuator>
      </transmission>
      <transmission name="trans_${prefix}joint_u">
         <type>transmission_interface/SimpleTransmission</type>
         <joint name="${prefix}joint_u">
            <hardwareInterface>hardware_interface/EffortJointInterface</hardwareInterface>
         </joint>
         <actuator name="${prefix}joint_u_motor">
            <hardwareInterface>hardware_interface/EffortJointInterface</hardwareInterface>
            <mechanicalReduction>1</mechanicalReduction>
         </actuator>
      </transmission>
      <transmission name="trans_${prefix}joint_r">
         <type>transmission_interface/SimpleTransmission</type>
         <joint name="${prefix}joint_r">
            <hardwareInterface>hardware_interface/EffortJointInterface</hardwareInterface>
         </joint>
         <actuator name="${prefix}joint_r_motor">
            <hardwareInterface>hardware_interface/EffortJointInterface</hardwareInterface>
            <mechanicalReduction>1</mechanicalReduction>
         </actuator>
      </transmission>
      <transmission name="trans_${prefix}joint_b">
         <type>transmission_interface/SimpleTransmission</type>
         <joint name="${prefix}joint_b">
            <hardwareInterface>hardware_interface/EffortJointInterface</hardwareInterface>
         </joint>
         <actuator name="${prefix}joint_b_motor">
            <hardwareInterface>hardware_interface/EffortJointInterface</hardwareInterface>
            <mechanicalReduction>1</mechanicalReduction>
         </actuator>
      </transmission>
      <transmission name="trans_${prefix}joint_t">
         <type>transmission_interface/SimpleTransmission</type>
         <joint name="${prefix}joint_t">
            <hardwareInterface>hardware_interface/EffortJointInterface</hardwareInterface>
         </joint>
         <actuator name="${prefix}joint_t_motor">
            <hardwareInterface>hardware_interface/EffortJointInterface</hardwareInterface>
            <mechanicalReduction>1</mechanicalReduction>
         </actuator>
      </transmission>

      <!-- gripper -->
      <link name="${prefix}finger_1">
         <inertial>
            <mass value=".1" />
            <origin rpy="0 0 0" xyz="0 0 0" />
            <inertia ixx="0.1" ixy="0" ixz="0" iyy="0.1" iyz="0" izz="0.1" />
         </inertial>
         <collision name="${prefix}right_finger_collision">
            <origin rpy="0 0 0" xyz="0 0 0" />
            <geometry>
               <mesh filename="package://motoman_sia20d_support/meshes/sia20d/visual/motoman_finger_1.STL" scale="1 1 1" />
            </geometry>
         </collision>
         <visual name="${prefix}right_finger_visual">
            <origin rpy="0 0 0" xyz="0 0 0" />
            <geometry>
               <mesh filename="package://motoman_sia20d_support/meshes/sia20d/collision/motoman_finger_1.STL" scale="1 1 1" />
            </geometry>
         </visual>
      </link>
      <link name="${prefix}finger_2">
         <inertial>
            <mass value=".1" />
            <origin rpy="0 0 0" xyz="0 0 0" />
            <inertia ixx="0.001" ixy="0" ixz="0" iyy="0.001" iyz="0" izz="0.001" />
         </inertial>
         <collision name="${prefix}left_finger_collision">
            <origin rpy="0 0 0" xyz="0 0 0" />
            <geometry>
               <mesh filename="package://motoman_sia20d_support/meshes/sia20d/collision/motoman_finger_2.STL" scale="1 1 1" />
            </geometry>
         </collision>
         <visual name="${prefix}left_finger_visual">
            <origin rpy="0 0 0" xyz="0 0 0" />
            <geometry>
               <mesh filename="package://motoman_sia20d_support/meshes/sia20d/visual/motoman_finger_2.STL" scale="1 1 1" />
            </geometry>
         </visual>
      </link>
      <joint name="${prefix}prism1" type="prismatic">
         <parent link="${prefix}link_t" />
         <child link="${prefix}finger_1" />
         <origin rpy="1.5708 0     0" xyz="0     0     0.00821" />
         <axis xyz="-1  0  0" />
         <limit effort="100.0" lower="-0.02" upper="0.0" velocity="10.0" />
      </joint>
      <joint name="${prefix}prism2" type="prismatic">
         <parent link="${prefix}link_t" />
         <child link="${prefix}finger_2" />
         <origin rpy="1.5708   0      -3.14159" xyz="0     0     0.00821" />
         <axis xyz="-1  0  0" />
         <limit effort="1000.0" lower="-0.02" upper="0.0" velocity="10.0" />
      </joint>
      <gazebo reference="${prefix}finger_1">
         <material>Gazebo/White</material>
         <turnGravityOff>true</turnGravityOff>
      </gazebo>
      <gazebo reference="${prefix}finger_2">
         <material>Gazebo/White</material>
         <turnGravityOff>true</turnGravityOff>
      </gazebo>

      <transmission name="trans_${prefix}prism1">
         <type>transmission_interface/SimpleTransmission</type>
         <joint name="${prefix}prism1">
            <hardwareInterface>hardware_interface/EffortJointInterface</hardwareInterface>
         </joint>
         <actuator name="${prefix}prism1_motor">
            <hardwareInterface>hardware_interface/EffortJointInterface</hardwareInterface>
            <mechanicalReduction>1</mechanicalReduction>
         </actuator>
      </transmission>
      <transmission name="trans_${prefix}prism2">
         <type>transmission_interface/SimpleTransmission</type>
         <joint name="${prefix}prism2">
            <hardwareInterface>hardware_interface/EffortJointInterface</hardwareInterface>
         </joint>
         <actuator name="${prefix}prism2_motor">
            <hardwareInterface>hardware_interface/EffortJointInterface</hardwareInterface>
            <mechanicalReduction>1</mechanicalReduction>
         </actuator>
      </transmission>
   </xacro:macro>
</robot>
